<?xml version="1.0" ?>
<!-- =================================================================================== -->
<!-- |    This document was autogenerated by xacro from urdf/robot.urdf.xacro          | -->
<!-- |    EDITING THIS FILE BY HAND IS NOT RECOMMENDED                                 | -->
<!-- =================================================================================== -->
<robot name="robot_bombero">
  <!-- MATERIAL -->
  <material name="blue">
    <color rgba="0.0 0.0 1.0 1.0"/>
  </material>
  <!-- FOOTPRINT (Plano de referencia del suelo) -->
  <link name="base_footprint"/>
  <!-- base_link (Marco principal del robot) -->
  <link name="base_link"/>
  <joint name="base_footprint_joint" type="fixed">
    <parent link="base_footprint"/>
    <child link="base_link"/>
    <origin rpy="0 0 0" xyz="0 0 0"/>
  </joint>
  <!-- CHASIS VISUAL -->
  <link name="chassis">
    <visual>
      <geometry>
        <box size="0.5 0.3 0.2"/>
      </geometry>
      <material name="blue"/>
    </visual>
    <collision>
      <geometry>
        <box size="0.5 0.3 0.2"/>
      </geometry>
    </collision>
    <inertial>
      <mass value="1.0"/>
      <origin xyz="0 0 0.1"/>
      <inertia ixx="0.01" ixy="0.0" ixz="0.0" iyy="0.01" iyz="0.0" izz="0.01"/>
    </inertial>
  </link>
  <!-- Unión fija entre base_link y chasis -->
  <joint name="chassis_joint" type="fixed">
    <parent link="base_link"/>
    <child link="chassis"/>
    <origin xyz="0 0 0.12"/>
  </joint>
  <link name="link_fl_wheel">
    <visual>
      <geometry>
        <cylinder length="0.05" radius="0.05"/>
      </geometry>
      <material name="grey">
        <color rgba="0.5 0.5 0.5 1.0"/>
      </material>
      <origin rpy="0 0 0" xyz="0 0 0"/>
    </visual>
    <collision>
      <geometry>
        <cylinder length="0.03" radius="0.05"/>
      </geometry>
      <origin rpy="0 0 0" xyz="0 0 0"/>
    </collision>
    <inertial>
      <mass value="0.2"/>
      <origin rpy="0 0 0" xyz="0 0 0"/>
      <inertia ixx="0.01" ixy="0.0" ixz="0.0" iyy="0.01" iyz="0.0" izz="0.01"/>
    </inertial>
  </link>
  <joint name="link_fl_wheel_joint" type="continuous">
    <parent link="base_link"/>
    <child link="link_fl_wheel"/>
    <origin rpy="1.5708 0 0" xyz="0.25 0.17 0.05"/>
    <axis xyz="0 0 1"/>
    <limit effort="100" lower="0" upper="3.14" velocity="1.0"/>
  </joint>
  <link name="link_fr_wheel">
    <visual>
      <geometry>
        <cylinder length="0.05" radius="0.05"/>
      </geometry>
      <material name="grey">
        <color rgba="0.5 0.5 0.5 1.0"/>
      </material>
      <origin rpy="0 0 0" xyz="0 0 0"/>
    </visual>
    <collision>
      <geometry>
        <cylinder length="0.03" radius="0.05"/>
      </geometry>
      <origin rpy="0 0 0" xyz="0 0 0"/>
    </collision>
    <inertial>
      <mass value="0.2"/>
      <origin rpy="0 0 0" xyz="0 0 0"/>
      <inertia ixx="0.01" ixy="0.0" ixz="0.0" iyy="0.01" iyz="0.0" izz="0.01"/>
    </inertial>
  </link>
  <joint name="link_fr_wheel_joint" type="continuous">
    <parent link="base_link"/>
    <child link="link_fr_wheel"/>
    <origin rpy="1.5708 0 0" xyz="0.25 -0.17 0.05"/>
    <axis xyz="0 0 1"/>
    <limit effort="100" lower="0" upper="3.14" velocity="1.0"/>
  </joint>
  <link name="link_rl_wheel">
    <visual>
      <geometry>
        <cylinder length="0.05" radius="0.05"/>
      </geometry>
      <material name="grey">
        <color rgba="0.5 0.5 0.5 1.0"/>
      </material>
      <origin rpy="0 0 0" xyz="0 0 0"/>
    </visual>
    <collision>
      <geometry>
        <cylinder length="0.03" radius="0.05"/>
      </geometry>
      <origin rpy="0 0 0" xyz="0 0 0"/>
    </collision>
    <inertial>
      <mass value="0.2"/>
      <origin rpy="0 0 0" xyz="0 0 0"/>
      <inertia ixx="0.01" ixy="0.0" ixz="0.0" iyy="0.01" iyz="0.0" izz="0.01"/>
    </inertial>
  </link>
  <joint name="link_rl_wheel_joint" type="continuous">
    <parent link="base_link"/>
    <child link="link_rl_wheel"/>
    <origin rpy="1.5708 0 0" xyz="-0.25 0.17 0.05"/>
    <axis xyz="0 0 1"/>
    <limit effort="100" lower="0" upper="3.14" velocity="1.0"/>
  </joint>
  <link name="link_rr_wheel">
    <visual>
      <geometry>
        <cylinder length="0.05" radius="0.05"/>
      </geometry>
      <material name="grey">
        <color rgba="0.5 0.5 0.5 1.0"/>
      </material>
      <origin rpy="0 0 0" xyz="0 0 0"/>
    </visual>
    <collision>
      <geometry>
        <cylinder length="0.03" radius="0.05"/>
      </geometry>
      <origin rpy="0 0 0" xyz="0 0 0"/>
    </collision>
    <inertial>
      <mass value="0.2"/>
      <origin rpy="0 0 0" xyz="0 0 0"/>
      <inertia ixx="0.01" ixy="0.0" ixz="0.0" iyy="0.01" iyz="0.0" izz="0.01"/>
    </inertial>
  </link>
  <joint name="link_rr_wheel_joint" type="continuous">
    <parent link="base_link"/>
    <child link="link_rr_wheel"/>
    <origin rpy="1.5708 0 0" xyz="-0.25 -0.17 0.05"/>
    <axis xyz="0 0 1"/>
    <limit effort="100" lower="0" upper="3.14" velocity="1.0"/>
  </joint>
  <!-- Desplazamiento de los ejes -->
  <material name="red">
    <color rgba="1.0 0.0 0.0 1.0"/>
    <!-- Rojo -->
  </material>
  <!-- Links del brazo -->
  <link name="link_waist">
    <collision>
      <origin rpy="0 0 0" xyz="0 0 0.025"/>
      <geometry>
        <box size="0.07 0.07 0.05"/>
      </geometry>
    </collision>
    <visual>
      <origin rpy="0 0 0" xyz="0 0 0.025"/>
      <geometry>
        <box size="0.07 0.07 0.05"/>
      </geometry>
      <material name="blue"/>
    </visual>
    <inertial>
      <origin rpy="0 0 0" xyz="0 0 0.025"/>
      <mass value="0.4"/>
      <inertia ixx="0.0002466666666666667" ixy="0.0" ixz="0.0" iyy="0.0002466666666666667" iyz="0.0" izz="0.00032666666666666673"/>
    </inertial>
  </link>
  <link name="link_shoulder">
    <collision>
      <origin rpy="0 0 0" xyz="0 0 0.15"/>
      <geometry>
        <box size="0.07 0.07 0.3"/>
      </geometry>
    </collision>
    <visual>
      <origin rpy="0 0 0" xyz="0 0 0.15"/>
      <geometry>
        <box size="0.07 0.07 0.3"/>
      </geometry>
      <material name="red"/>
    </visual>
    <inertial>
      <origin rpy="0 0 0" xyz="0 0 0.15"/>
      <mass value="0.4"/>
      <inertia ixx="0.003163333333333333" ixy="0.0" ixz="0.0" iyy="0.003163333333333333" iyz="0.0" izz="0.00032666666666666673"/>
    </inertial>
  </link>
  <link name="link_elbow">
    <collision>
      <origin rpy="0 0 0" xyz="0 0 0.1"/>
      <geometry>
        <box size="0.07 0.07 0.2"/>
      </geometry>
    </collision>
    <visual>
      <origin rpy="0 0 0" xyz="0 0 0.1"/>
      <geometry>
        <box size="0.07 0.07 0.2"/>
      </geometry>
      <material name="blue"/>
    </visual>
    <inertial>
      <origin rpy="0 0 0" xyz="0 0 0.1"/>
      <mass value="0.4"/>
      <inertia ixx="0.001496666666666667" ixy="0.0" ixz="0.0" iyy="0.001496666666666667" iyz="0.0" izz="0.00032666666666666673"/>
    </inertial>
  </link>
  <link name="link_wrist">
    <collision>
      <origin rpy="0 0 0" xyz="0 0 0.05"/>
      <geometry>
        <box size="0.07 0.07 0.1"/>
      </geometry>
    </collision>
    <visual>
      <origin rpy="0 0 0" xyz="0 0 0.05"/>
      <geometry>
        <box size="0.07 0.07 0.1"/>
      </geometry>
      <material name="red"/>
    </visual>
    <inertial>
      <origin rpy="0 0 0" xyz="0 0 0.05"/>
      <mass value="0.4"/>
      <inertia ixx="0.0004966666666666667" ixy="0.0" ixz="0.0" iyy="0.0004966666666666667" iyz="0.0" izz="0.00032666666666666673"/>
    </inertial>
  </link>
  <!-- Joints del brazo -->
  <joint name="joint_waist" type="revolute">
    <parent link="chassis"/>
    <child link="link_waist"/>
    <origin xyz="0.1 0 0.1"/>
    <axis xyz="0 0 1"/>
    <limit effort="100" lower="-1.5" upper="1.5" velocity="1.0"/>
  </joint>
  <joint name="joint_shoulder" type="revolute">
    <parent link="link_waist"/>
    <child link="link_shoulder"/>
    <origin rpy="0 0 0" xyz="0 0 0.05"/>
    <axis xyz="0 1 0"/>
    <limit effort="100" lower="-1.5" upper="1.5" velocity="1.0"/>
  </joint>
  <joint name="joint_elbow" type="revolute">
    <parent link="link_shoulder"/>
    <child link="link_elbow"/>
    <origin rpy="0 0 0" xyz="0 0 0.3"/>
    <axis xyz="0 1 0"/>
    <limit effort="100" lower="-1.5" upper="1.5" velocity="1.0"/>
  </joint>
  <joint name="joint_wrist" type="revolute">
    <parent link="link_elbow"/>
    <child link="link_wrist"/>
    <origin rpy="0 0 0" xyz="0 0 0.2"/>
    <axis xyz="0 1 0"/>
    <limit effort="100" lower="-1.5" upper="1.5" velocity="1.0"/>
  </joint>
  <material name="green">
    <color rgba="0.0 1.0 0.0 1.0"/>
  </material>
  <!-- Sensor térmico -->
  <link name="link_thermal_sensor">
    <visual>
      <geometry>
        <box size="0.03 0.03 0.02"/>
      </geometry>
      <material name="red">
        <color rgba="1.0 0.0 0.0 1.0"/>
      </material>
    </visual>
    <collision>
      <geometry>
        <box size="0.03 0.03 0.02"/>
      </geometry>
    </collision>
    <inertial>
      <mass value="0.02"/>
      <inertia ixx="0.000005" ixy="0.0" ixz="0.0" iyy="0.000005" iyz="0.0" izz="0.000005"/>
      <origin rpy="0 0 0" xyz="0 0 0"/>
    </inertial>
  </link>
  <joint name="joint_thermal_sensor" type="fixed">
    <parent link="base_link"/>
    <child link="link_thermal_sensor"/>
    <origin rpy="0 0 0" xyz="0.26 0.05 0.10"/>
  </joint>
  <!-- Sharp Front -->
  <link name="link_sharp_front">
    <visual>
      <geometry>
        <box size="0.03 0.03 0.02"/>
      </geometry>
      <material name="green">
        <color rgba="0.0 1.0 0.0 1.0"/>
      </material>
    </visual>
    <collision>
      <geometry>
        <box size="0.03 0.03 0.02"/>
      </geometry>
    </collision>
  </link>
  <joint name="joint_sharp_front" type="fixed">
    <parent link="base_link"/>
    <child link="link_sharp_front"/>
    <origin rpy="0 0 0" xyz="0.26 0 0.1"/>
  </joint>
  <!-- Sharp Left -->
  <link name="link_sharp_left">
    <visual>
      <geometry>
        <box size="0.03 0.03 0.02"/>
      </geometry>
      <material name="green"/>
    </visual>
    <collision>
      <geometry>
        <box size="0.03 0.03 0.02"/>
      </geometry>
    </collision>
  </link>
  <joint name="joint_sharp_left" type="fixed">
    <parent link="base_link"/>
    <child link="link_sharp_left"/>
    <origin rpy="0 0 0" xyz="0 0.15 0.1"/>
  </joint>
  <!-- Sharp Right -->
  <link name="link_sharp_right">
    <visual>
      <geometry>
        <box size="0.03 0.03 0.02"/>
      </geometry>
      <material name="green"/>
    </visual>
    <collision>
      <geometry>
        <box size="0.03 0.03 0.02"/>
      </geometry>
    </collision>
  </link>
  <joint name="joint_sharp_right" type="fixed">
    <parent link="base_link"/>
    <child link="link_sharp_right"/>
    <origin rpy="0 0 0" xyz="0 -0.15 0.1"/>
  </joint>
  <!-- IMU -->
  <link name="link_imu">
    <visual>
      <geometry>
        <box size="0.025 0.025 0.015"/>
      </geometry>
      <material name="blue">
        <color rgba="0.0 0.0 1.0 1.0"/>
      </material>
    </visual>
    <collision>
      <geometry>
        <box size="0.025 0.025 0.015"/>
      </geometry>
    </collision>
  </link>
  <joint name="joint_imu" type="fixed">
    <parent link="base_link"/>
    <child link="link_imu"/>
    <origin rpy="0 0 0" xyz="0 0 0.1"/>
  </joint>
  <link name="link_camera">
    <visual>
      <geometry>
        <box size="0.04 0.04 0.02"/>
      </geometry>
      <material name="dark_gray">
        <color rgba="0.2 0.2 0.2 1.0"/>
      </material>
    </visual>
    <collision>
      <geometry>
        <box size="0.04 0.04 0.02"/>
      </geometry>
    </collision>
    <inertial>
      <mass value="0.05"/>
      <inertia ixx="0.00001" ixy="0.0" ixz="0.0" iyy="0.00001" iyz="0.0" izz="0.00001"/>
      <origin rpy="0 0 0" xyz="0 0 0"/>
    </inertial>
  </link>
  <joint name="joint_camera" type="fixed">
    <parent link="link_wrist"/>
    <child link="link_camera"/>
    <origin rpy="0 0 0" xyz="0 0 0.1"/>
  </joint>
  <link name="water_pump_link">
    <visual>
      <geometry>
        <cylinder length="0.1" radius="0.03"/>
      </geometry>
      <material name="red">
        <color rgba="1.0 0.0 0.0 1.0"/>
      </material>
    </visual>
  </link>
  <joint name="joint_water_pump" type="fixed">
    <parent link="chassis"/>
    <child link="water_pump_link"/>
    <origin rpy="0 1.57 1.57" xyz="-0.1 0 0.1"/>
  </joint>
  <ros2_control name="FirebotSystem" type="system">
    <hardware>
      <plugin>firebot_hardware/FirebotHardwareInterface</plugin>
      <param name="port_name">/dev/ttyUSB0</param>
    </hardware>
    <!-- Actuadores de ruedas mecanum -->
    <joint name="link_fl_wheel_joint">
      <command_interface name="velocity"/>
      <state_interface name="velocity"/>
    </joint>
    <joint name="link_fr_wheel_joint">
      <command_interface name="velocity"/>
      <state_interface name="velocity"/>
    </joint>
    <joint name="link_rl_wheel_joint">
      <command_interface name="velocity"/>
      <state_interface name="velocity"/>
    </joint>
    <joint name="link_rr_wheel_joint">
      <command_interface name="velocity"/>
      <state_interface name="velocity"/>
    </joint>
    <!-- Articulaciones del brazo -->
    <joint name="joint_waist">
      <command_interface name="position"/>
      <state_interface name="position"/>
    </joint>
    <joint name="joint_shoulder">
      <command_interface name="position"/>
      <state_interface name="position"/>
    </joint>
    <joint name="joint_elbow">
      <command_interface name="position"/>
      <state_interface name="position"/>
    </joint>
    <joint name="joint_wrist">
      <command_interface name="position"/>
      <state_interface name="position"/>
    </joint>
    <!-- Actuador para bomba de agua -->
    <joint name="joint_water_pump">
      <command_interface name="effort"/>
      <state_interface name="effort"/>
    </joint>
    <!--Informacion sensores -->
    <sensor name="imu_sensor">
      <state_interface name="angular_velocity.x"/>
      <state_interface name="angular_velocity.y"/>
      <state_interface name="angular_velocity.z"/>
      <state_interface name="linear_acceleration.x"/>
      <state_interface name="linear_acceleration.y"/>
      <state_interface name="linear_acceleration.z"/>
    </sensor>
    <gpio name="sharp_front">
      <state_interface name="analog_output"/>
    </gpio>
    <gpio name="sharp_left">
      <state_interface name="analog_output"/>
    </gpio>
    <gpio name="sharp_right">
      <state_interface name="analog_output"/>
    </gpio>
  </ros2_control>
</robot>
